Workbook

Sheet WBS_계획
A1: Unity 기능 중심 차량 컨피규레이터(팀 yeyu) WBS
A4: 프로젝트 범위: 외관·기능 옵션 선택 후 옵션 미적용/적용 차량을 분할 화면으로 비교하는 Unity 컨피규레이터 | 기간: 2026-10-06 ~ 2026-10-14
A6: WBS ID | B6: 대분류 | C6: 중분류 | D6: 작업 패키지 | E6: 주요 산출물 | F6: 담당자 | G6: 시작일 | H6: 종료일 | I6: 기간(일) | J6: 선행 작업 | K6: 우선순위 | L6: 상태 | M6: 진척률 | N6: 완료 기준 | O6: 비고
A7: A.1 | B7: 프로젝트 관리 | C7: 기획 | D7: 기능 옵션 4종·시나리오 확정 | E7: 옵션 목록, 시나리오 흐름 | F7: 공동 | G7: 46301 | H7: 46301 | I7: =IF(OR(G7="",H7=""),"",H7-G7+1) -> 1 | K7: 높음 | L7: 완료 | M7: 1 | N7: 주행 2종·주차 2종, 분할 화면 비교 방식 확정
A8: A.2 | B8: 프로젝트 관리 | C8: 문서 | D8: 계획서·SRS v0.2·README 작성 | E8: SRS.md, README.md | F8: 김예은 | G8: 46301 | H8: 46301 | I8: =IF(OR(G8="",H8=""),"",H8-G8+1) -> 1 | J8: A.1 | K8: 높음 | L8: 완료 | M8: 1 | N8: FR-01~39, NFR-01~09 ID·기준 명시
A9: A.3 | B9: 프로젝트 관리 | C9: 설계 | D9: 공통 구조 확정 (CarConfig 필드, 영역 좌표, 레이어·태그, 차량 에셋) | E9: SRS 부록 A, 차량 에셋 | F9: 공동 | G9: 46301 | H9: 46301 | I9: =IF(OR(G9="",H9=""),"",H9-G9+1) -> 1 | J9: A.2 | K9: 높음 | L9: 미착수 | M9: 0 | N9: CarConfig 7개 필드·영역 X좌표 합의 | O9: 크리티컬 패스
A10: A.4 | B10: 프로젝트 관리 | C10: 협업 | D10: GitHub 저장소·main/dev 브랜치, .gitignore, Git LFS, Force Text | E10: GitHub 저장소 | F10: 김예은 | G10: 46301 | H10: 46301 | I10: =IF(OR(G10="",H10=""),"",H10-G10+1) -> 1 | K10: 높음 | L10: 미착수 | M10: 0 | N10: 두 PC에서 clone·push 성공 | O10: NFR-08
A11: A.5 | B11: 프로젝트 관리 | C11: 환경 | D11: Unity 버전 통일, 두 PC에서 프로젝트 열기 확인 | E11: Unity 프로젝트 | F11: 공동 | G11: 46301 | H11: 46301 | I11: =IF(OR(G11="",H11=""),"",H11-G11+1) -> 1 | J11: A.4 | K11: 중간 | L11: 미착수 | M11: 0 | N11: 같은 버전으로 오류 없이 열림 | O11: NFR-07
A12: A.6 | B12: 프로젝트 관리 | C12: 일정 | D12: WBS·간트 관리, 매일 19:00 진척 갱신 | E12: WBS 엑셀 | F12: 공동 | G12: 46301 | H12: 46309 | I12: =IF(OR(G12="",H12=""),"",H12-G12+1) -> 9 | J12: A.2 | K12: 중간 | L12: 진행중 | M12: 0.1 | N12: 매일 상태·진척률 갱신
A13: B.1 | B13: 공통 기반 | C13: 영역 전환 | D13: MainScene·ModeManager·AreaBase (Additive 로드·전환·초기화) | E13: ModeManager.cs, AreaBase.cs | F13: 김예은 | G13: 46302 | H13: 46302 | I13: =IF(OR(G13="",H13=""),"",H13-G13+1) -> 1 | J13: A.3 | K13: 높음 | L13: 미착수 | M13: 0 | N13: 버튼으로 영역 전환 1초 이내, 조명 전환 | O13: FR-36~39
A14: B.2 | B14: 공통 기반 | C14: 차량 | D14: 공통 차량 프리팹, CarController (WheelCollider, 스크립트 입력) | E14: Car.prefab, CarController.cs | F14: 김예은 | G14: 46302 | H14: 46302 | I14: =IF(OR(G14="",H14=""),"",H14-G14+1) -> 1 | J14: A.3 | K14: 높음 | L14: 미착수 | M14: 0 | N14: 스크립트 입력으로 가속·조향·제동 | O14: 크리티컬 패스, 두 파트 선행
A15: B.3 | B15: 공통 기반 | C15: UI | D15: ConfiguratorArea 쇼룸, UI-01 외관 선택, UI-02 기능 선택 | E15: ConfiguratorArea.unity | F15: 강유나 | G15: 46302 | H15: 46302 | I15: =IF(OR(G15="",H15=""),"",H15-G15+1) -> 1 | J15: A.3 | K15: 높음 | L15: 미착수 | M15: 0 | N15: 외관 버튼·기능 체크박스·시작 버튼 동작 | O15: FR-04~06
A16: B.4 | B16: 공통 기반 | C16: 외관 | D16: CarConfig, CarAppearance (색상·트림·휠) | E16: CarConfig.cs, CarAppearance.cs | F16: 강유나 | G16: 46302 | H16: 46302 | I16: =IF(OR(G16="",H16=""),"",H16-G16+1) -> 1 | J16: A.3 | K16: 높음 | L16: 미착수 | M16: 0 | N16: 색상 0.5초 이내 변경, 트림·휠 교체 | O16: FR-01~03
A17: B.5 | B17: 공통 기반 | C17: 카메라 | D17: SplitScreenManager, CameraSwitcher | E17: SplitScreenManager.cs, CameraSwitcher.cs | F17: 공동 | G17: 46303 | H17: 46303 | I17: =IF(OR(G17="",H17=""),"",H17-G17+1) -> 1 | J17: B.1;B.2 | K17: 높음 | L17: 미착수 | M17: 0 | N17: 좌우 분할, 양쪽 시점 동시 전환 | O17: FR-11, FR-12
A18: B.6 | B18: 공통 기반 | C18: 통합 | D18: 공통 기반 dev 병합, 두 PC에서 모드 전환 확인 | E18: dev 브랜치 | F18: 공동 | G18: 46302 | H18: 46302 | I18: =IF(OR(G18="",H18=""),"",H18-G18+1) -> 1 | J18: B.1;B.2;B.3;B.4 | K18: 높음 | L18: 미착수 | M18: 0 | N18: 두 PC 모두 모드 전환 동작 | O18: M2
A19: C.1 | B19: 주행 기능 | C19: 맵 | D19: DrivingArea: 야간 도로 코스 2벌, 조명, 보행자 트리거 | E19: DrivingArea.unity, Pedestrian.prefab | F19: 김예은 | G19: 46303 | H19: 46303 | I19: =IF(OR(G19="",H19=""),"",H19-G19+1) -> 1 | J19: B.6 | K19: 높음 | L19: 미착수 | M19: 0 | N19: 코스 A·B 동일, 헤드램프 50m | O19: FR-08
A20: C.2 | B20: 주행 기능 | C20: 나이트 비전 | D20: NightVisionSensor: 120m 감지, TTC, 경고·감속 | E20: NightVisionSensor.cs | F20: 김예은 | G20: 46303 | H20: 46304 | I20: =IF(OR(G20="",H20=""),"",H20-G20+1) -> 2 | J20: C.1 | K20: 높음 | L20: 미착수 | M20: 0 | N20: TTC 4초 경고, 2.5초 감속, 10m 이상 앞 정지 | O20: FR-15, FR-17
A21: C.3 | B21: 주행 기능 | C21: 나이트 비전 | D21: NightVisionDisplay: 적외선 화면, 노란 박스 | E21: NightVisionDisplay.cs | F21: 김예은 | G21: 46304 | H21: 46304 | I21: =IF(OR(G21="",H21=""),"",H21-G21+1) -> 1 | J21: C.2 | K21: 높음 | L21: 미착수 | M21: 0 | N21: 클러스터 흑백 화면에 보행자 박스 | O21: FR-16
A22: C.4 | B22: 주행 기능 | C22: 나이트 비전 | D22: 미적용 차량 가상 운전자 (반응 1초 후 급제동) | E22: VirtualDriver.cs | F22: 김예은 | G22: 46304 | H22: 46304 | I22: =IF(OR(G22="",H22=""),"",H22-G22+1) -> 1 | J22: C.2 | K22: 높음 | L22: 미착수 | M22: 0 | N22: 보행자 50m 진입 후에야 감속 | O22: TC-07
A23: C.5 | B23: 주행 기능 | C23: 시각화 | D23: BirdViewOverlay: 헤드램프·적외선 원뿔 | E23: BirdViewOverlay.cs | F23: 김예은 | G23: 46304 | H23: 46304 | I23: =IF(OR(G23="",H23=""),"",H23-G23+1) -> 1 | J23: C.2 | K23: 높음 | L23: 미착수 | M23: 0 | N23: 버드뷰에 원뿔 2개 표시 | O23: FR-18
A24: C.6 | B24: 주행 기능 | C24: 맵 | D24: 골목 맵, 회전 궤적 측정 후 골목 폭 확정 | E24: DrivingArea.unity | F24: 김예은 | G24: 46305 | H24: 46305 | I24: =IF(OR(G24="",H24=""),"",H24-G24+1) -> 1 | J24: C.1 | K24: 높음 | L24: 미착수 | M24: 0 | N24: OFF는 3점 턴, ON은 한 번에 유턴 가능한 폭 | O24: FR-21
... A27: C.9 | B27: 주행 기능 | C27: 추가 | D27: (Should) 거리·TTC 표시, 동위상 2도 | E27: - | F27: 김예은 | G27: 46307 | H27: 46308 | I27: =IF(OR(G27="",H27=""),"",H27-G27+1) -> 2 | J27: C.8 | K27: 중간 | L27: 미착수 | M27: 0 | N27: 수치 UI 표시, 60km/h 이상 동위상 | O27: FR-19, FR-24
A28: C.10 | B28: 주행 기능 | C28: 추가 | D28: (Could) 뒷바퀴 조향각 아이콘 | E28: - | F28: 김예은 | I28: =IF(OR(G28="",H28=""),"",H28-G28+1) | J28: C.8 | K28: 낮음 | L28: 보류 | M28: 0 | N28: 클러스터 아이콘 표시 | O28: FR-25
A29: D.1 | B29: 주차 기능 | C29: 맵 | D29: ParkingArea: 주차장 2벌, 조명, 격자 맵 | E29: ParkingArea.unity, GridMap.cs | F29: 강유나 | G29: 46303 | H29: 46303 | I29: =IF(OR(G29="",H29=""),"",H29-G29+1) -> 1 | J29: B.6 | K29: 높음 | L29: 미착수 | M29: 0 | N29: 주차장 A·B 동일 격자 | O29: FR-09
A30: D.2 | B30: 주차 기능 | C30: 발렛 | D30: A* 경로 계획, 빈 주차면 배정 | E30: AStarPlanner.cs | F30: 강유나 | G30: 46303 | H30: 46303 | I30: =IF(OR(G30="",H30=""),"",H30-G30+1) -> 1 | J30: D.1 | K30: 높음 | L30: 미착수 | M30: 0 | N30: 배정 주차면까지 경로 생성 | O30: FR-26
A31: D.3 | B31: 주차 기능 | C31: 발렛 | D31: 예약 테이블 ON·OFF | E31: ReservationTable.cs | F31: 강유나 | G31: 46304 | H31: 46304 | I31: =IF(OR(G31="",H31=""),"",H31-G31+1) -> 1 | J31: D.2 | K31: 높음 | L31: 미착수 | M31: 0 | N31: ON 충돌 0회, OFF 겹침 정지 1회 이상 | O31: FR-27, FR-28
A32: D.4 | B32: 주차 기능 | C32: 시각화 | D32: 버드뷰 예약 셀 차량 색 표시 | E32: - | F32: 강유나 | G32: 46304 | H32: 46304 | I32: =IF(OR(G32="",H32=""),"",H32-G32+1) -> 1 | J32: D.3 | K32: 높음 | L32: 미착수 | M32: 0 | N32: 차량별 예약 셀 색 표시 | O32: FR-29
A33: D.5 | B33: 주차 기능 | C33: 원격 주차 | D33: 스마트키 원격 주차, UI-06, 0.2초 정지 | E33: RemoteParking.cs | F33: 강유나 | G33: 46305 | H33: 46305 | I33: =IF(OR(G33="",H33=""),"",H33-G33+1) -> 1 | J33: D.1 | K33: 높음 | L33: 미착수 | M33: 0 | N33: 버튼 누르는 동안 이동, 떼면 0.2초 내 정지 | O33: FR-31, FR-32
A34: D.6 | B34: 주차 기능 | C34: 원격 주차 | D34: 장애물 0.3m 정지, 문 열림 공간 부족 표시 | E34: - | F34: 강유나 | G34: 46306 | H34: 46306 | I34: =IF(OR(G34="",H34=""),"",H34-G34+1) -> 1 | J34: D.5 | K34: 높음 | L34: 미착수 | M34: 0 | N34: OFF 쪽 문 열림 영역 빨간색 | O34: FR-33, FR-34
A35: D.7 | B35: 주차 기능 | C35: 추가 | D35: (Should) 상태 표시, 문 열림 반경 | E35: - | F35: 강유나 | G35: 46307 | H35: 46308 | I35: =IF(OR(G35="",H35=""),"",H35-G35+1) -> 2 | J35: D.6 | K35: 중간 | L35: 미착수 | M35: 0 | N35: 남은 거리·대기 상태 표시 | O35: FR-30, FR-35
A36: E.1 | B36: 통합·시험 | C36: 시나리오 | D36: 주행 ScenarioManager, 두 차량 동시 출발 | E36: DrivingScenario.cs | F36: 김예은 | G36: 46307 | H36: 46307 | I36: =IF(OR(G36="",H36=""),"",H36-G36+1) -> 1 | J36: C.8 | K36: 높음 | L36: 미착수 | M36: 0 | N36: 출발~골목 유턴까지 끊김 없음 | O36: FR-11, NFR-02
A37: E.2 | B37: 통합·시험 | C37: 시나리오 | D37: 주차 ScenarioManager | E37: ParkingScenario.cs | F37: 강유나 | G37: 46307 | H37: 46307 | I37: =IF(OR(G37="",H37=""),"",H37-G37+1) -> 1 | J37: D.6 | K37: 높음 | L37: 미착수 | M37: 0 | N37: 발렛~원격 주차까지 끊김 없음 | O37: FR-11, NFR-02
A38: E.3 | B38: 통합·시험 | C38: 통합 | D38: 모드 전환 통합 (반복 전환 시 초기화·조명) | E38: - | F38: 공동 | G38: 46307 | H38: 46307 | I38: =IF(OR(G38="",H38=""),"",H38-G38+1) -> 1 | J38: E.1;E.2 | K38: 높음 | L38: 미착수 | M38: 0 | N38: 2회 연속 실행 시 시작 상태 동일 | O38: FR-37~39, TC-18
A39: E.4 | B39: 통합·시험 | C39: 추가 | D39: (Could) 결과 패널, 일시정지 | E39: UI-05 | F39: 공동 | I39: =IF(OR(G39="",H39=""),"",H39-G39+1) | J39: E.3 | K39: 낮음 | L39: 보류 | M39: 0 | N39: 결과 요약 표시 | O39: FR-13, FR-14
A40: E.5 | B40: 통합·시험 | C40: 시험 | D40: 주행 TC 수행 (TC-02~10) | E40: SRS 7.2 결과 | F40: 김예은 | G40: 46308 | H40: 46308 | I40: =IF(OR(G40="",H40=""),"",H40-G40+1) -> 1 | J40: E.3 | K40: 높음 | L40: 미착수 | M40: 0 | N40: Must TC 전부 PASS
A41: E.6 | B41: 통합·시험 | C41: 시험 | D41: 주차 TC 수행 (TC-11~15) | E41: SRS 7.2 결과 | F41: 강유나 | G41: 46308 | H41: 46308 | I41: =IF(OR(G41="",H41=""),"",H41-G41+1) -> 1 | J41: E.3 | K41: 높음 | L41: 미착수 | M41: 0 | N41: Must TC 전부 PASS
A42: E.7 | B42: 통합·시험 | C42: 시험 | D42: 공통 TC (TC-01, 16~18, 20~23): fps, 재현성, 전환 시간 | E42: 측정 기록 | F42: 공동 | G42: 46308 | H42: 46308 | I42: =IF(OR(G42="",H42=""),"",H42-G42+1) -> 1 | J42: E.3 | K42: 높음 | L42: 미착수 | M42: 0 | N42: 평균 60fps, 5회 결과 일치 | O42: NFR-01~03, NFR-09
A43: E.8 | B43: 통합·시험 | C43: 시험 | D43: 버그 수정 | E43: - | F43: 공동 | G43: 46308 | H43: 46308 | I43: =IF(OR(G43="",H43=""),"",H43-G43+1) -> 1 | J43: E.5;E.6;E.7 | K43: 높음 | L43: 미착수 | M43: 0 | N43: 차단 버그 0건
A44: E.9 | B44: 통합·시험 | C44: 빌드 | D44: Windows 최종 빌드, 시연 PC 확인 | E44: 실행 파일 | F44: 김예은 | G44: 46308 | H44: 46308 | I44: =IF(OR(G44="",H44=""),"",H44-G44+1) -> 1 | J44: E.8 | K44: 높음 | L44: 미착수 | M44: 0 | N44: 시연 PC에서 단독 실행 | O44: NFR-07
A45: F.1 | B45: 문서·발표 | C45: 시연영상 | D45: 시연 영상 녹화 (주행·주차, 운전석·버드뷰) | E45: 시연 영상 | F45: 공동 | G45: 46308 | H45: 46308 | I45: =IF(OR(G45="",H45=""),"",H45-G45+1) -> 1 | J45: E.9 | K45: 높음 | L45: 미착수 | M45: 0 | N45: 4개 기능 ON/OFF 비교 녹화
...

Sheet Gantt_9일
A1: Unity 기능 중심 차량 컨피규레이터 WBS — 9일 간트 차트
A3: 막대 색: 김예은 파랑 · 강유나 주황 · 공동 초록 · ◆ 마일스톤. 날짜·담당·상태는 WBS_계획 시트에서 수정하면 자동 반영됩니다.
A4: WBS ID | B4: 작업 패키지 | C4: 담당자 | D4: 상태 | E4: 1주차 (10/6~10/11) | K4: 2주차 (10/12~10/14)
E5: 46301 | F5: 46302 | G5: 46303 | H5: 46304 | I5: 46305 | J5: 46306 | K5: 46307 | L5: 46308 | M5: 46309
A6: A.1 | B6: =VLOOKUP($A6,WBS_계획!$A:$O,4,FALSE()) -> 기능 옵션 4종·시나리오 확정 | C6: =VLOOKUP($A6,WBS_계획!$A:$O,6,FALSE()) -> 공동 | D6: =VLOOKUP($A6,WBS_계획!$A:$O,12,FALSE()) -> 완료 | E6: =IF(ISNUMBER(VLOOKUP($A6,WBS_계획!$A:$O,7,FALSE())),IF(AND(E$5>=VLOOKUP($A6,WBS_계획!$A:$O,7,FALSE()),E$5<=VLOOKUP($A6,WBS_계획!$A:$O,8,FALSE())),IF(LEFT($A6,1)="M","◆","■"),""),"") -> ■ | F6: =IF(ISNUMBER(VLOOKUP($A6,WBS_계획!$A:$O,7,FALSE())),IF(AND(F$5>=VLOOKUP($A6,WBS_계획!$A:$O,7,FALSE()),F$5<=VLOOKUP($A6,WBS_계획!$A:$O,8,FALSE())),IF(LEFT($A6,1)="M","◆","■"),""),"") | G6: =IF(ISNUMBER(VLOOKUP($A6,WBS_계획!$A:$O,7,FALSE())),IF(AND(G$5>=VLOOKUP($A6,WBS_계획!$A:$O,7,FALSE()),G$5<=VLOOKUP($A6,WBS_계획!$A:$O,8,FALSE())),IF(LEFT($A6,1)="M","◆","■"),""),"") | H6: =IF(ISNUMBER(VLOOKUP($A6,WBS_계획!$A:$O,7,FALSE())),IF(AND(H$5>=VLOOKUP($A6,WBS_계획!$A:$O,7,FALSE()),H$5<=VLOOKUP($A6,WBS_계획!$A:$O,8,FALSE())),IF(LEFT($A6,1)="M","◆","■"),""),"") | I6: =IF(ISNUMBER(VLOOKUP($A6,WBS_계획!$A:$O,7,FALSE())),IF(AND(I$5>=VLOOKUP($A6,WBS_계획!$A:$O,7,FALSE()),I$5<=VLOOKUP($A6,WBS_계획!$A:$O,8,FALSE())),IF(LEFT($A6,1)="M","◆","■"),""),"") | J6: =IF(ISNUMBER(VLOOKUP($A6,WBS_계획!$A:$O,7,FALSE())),IF(AND(J$5>=VLOOKUP($A6,WBS_계획!$A:$O,7,FALSE()),J$5<=VLOOKUP($A6,WBS_계획!$A:$O,8,FALSE())),IF(LEFT($A6,1)="M","◆","■"),""),"") | K6: =IF(ISNUMBER(VLOOKUP($A6,WBS_계획!$A:$O,7,FALSE())),IF(AND(K$5>=VLOOKUP($A6,WBS_계획!$A:$O,7,FALSE()),K$5<=VLOOKUP($A6,WBS_계획!$A:$O,8,FALSE())),IF(LEFT($A6,1)="M","◆","■"),""),"") | L6: =IF(ISNUMBER(VLOOKUP($A6,WBS_계획!$A:$O,7,FALSE())),IF(AND(L$5>=VLOOKUP($A6,WBS_계획!$A:$O,7,FALSE()),L$5<=VLOOKUP($A6,WBS_계획!$A:$O,8,FALSE())),IF(LEFT($A6,1)="M","◆","■"),""),"") | M6: =IF(ISNUMBER(VLOOKUP($A6,WBS_계획!$A:$O,7,FALSE())),IF(AND(M$5>=VLOOKUP($A6,WBS_계획!$A:$O,7,FALSE()),M$5<=VLOOKUP($A6,WBS_계획!$A:$O,8,FALSE())),IF(LEFT($A6,1)="M","◆","■"),""),"")
A7: A.2 | B7: =VLOOKUP($A7,WBS_계획!$A:$O,4,FALSE()) -> 계획서·SRS v0.2·README 작성 | C7: =VLOOKUP($A7,WBS_계획!$A:$O,6,FALSE()) -> 김예은 | D7: =VLOOKUP($A7,WBS_계획!$A:$O,12,FALSE()) -> 완료 | E7: =IF(ISNUMBER(VLOOKUP($A7,WBS_계획!$A:$O,7,FALSE())),IF(AND(E$5>=VLOOKUP($A7,WBS_계획!$A:$O,7,FALSE()),E$5<=VLOOKUP($A7,WBS_계획!$A:$O,8,FALSE())),IF(LEFT($A7,1)="M","◆","■"),""),"") -> ■ | F7: =IF(ISNUMBER(VLOOKUP($A7,WBS_계획!$A:$O,7,FALSE())),IF(AND(F$5>=VLOOKUP($A7,WBS_계획!$A:$O,7,FALSE()),F$5<=VLOOKUP($A7,WBS_계획!$A:$O,8,FALSE())),IF(LEFT($A7,1)="M","◆","■"),""),"") | G7: =IF(ISNUMBER(VLOOKUP($A7,WBS_계획!$A:$O,7,FALSE())),IF(AND(G$5>=VLOOKUP($A7,WBS_계획!$A:$O,7,FALSE()),G$5<=VLOOKUP($A7,WBS_계획!$A:$O,8,FALSE())),IF(LEFT($A7,1)="M","◆","■"),""),"") | H7: =IF(ISNUMBER(VLOOKUP($A7,WBS_계획!$A:$O,7,FALSE())),IF(AND(H$5>=VLOOKUP($A7,WBS_계획!$A:$O,7,FALSE()),H$5<=VLOOKUP($A7,WBS_계획!$A:$O,8,FALSE())),IF(LEFT($A7,1)="M","◆","■"),""),"") | I7: =IF(ISNUMBER(VLOOKUP($A7,WBS_계획!$A:$O,7,FALSE())),IF(AND(I$5>=VLOOKUP($A7,WBS_계획!$A:$O,7,FALSE()),I$5<=VLOOKUP($A7,WBS_계획!$A:$O,8,FALSE())),IF(LEFT($A7,1)="M","◆","■"),""),"") | J7: =IF(ISNUMBER(VLOOKUP($A7,WBS_계획!$A:$O,7,FALSE())),IF(AND(J$5>=VLOOKUP($A7,WBS_계획!$A:$O,7,FALSE()),J$5<=VLOOKUP($A7,WBS_계획!$A:$O,8,FALSE())),IF(LEFT($A7,1)="M","◆","■"),""),"") | K7: =IF(ISNUMBER(VLOOKUP($A7,WBS_계획!$A:$O,7,FALSE())),IF(AND(K$5>=VLOOKUP($A7,WBS_계획!$A:$O,7,FALSE()),K$5<=VLOOKUP($A7,WBS_계획!$A:$O,8,FALSE())),IF(LEFT($A7,1)="M","◆","■"),""),"") | L7: =IF(ISNUMBER(VLOOKUP($A7,WBS_계획!$A:$O,7,FALSE())),IF(AND(L$5>=VLOOKUP($A7,WBS_계획!$A:$O,7,FALSE()),L$5<=VLOOKUP($A7,WBS_계획!$A:$O,8,FALSE())),IF(LEFT($A7,1)="M","◆","■"),""),"") | M7: =IF(ISNUMBER(VLOOKUP($A7,WBS_계획!$A:$O,7,FALSE())),IF(AND(M$5>=VLOOKUP($A7,WBS_계획!$A:$O,7,FALSE()),M$5<=VLOOKUP($A7,WBS_계획!$A:$O,8,FALSE())),IF(LEFT($A7,1)="M","◆","■"),""),"")
A8: A.3 | B8: =VLOOKUP($A8,WBS_계획!$A:$O,4,FALSE()) -> 공통 구조 확정 (CarConfig 필드, 영역 좌표, 레이어·태그, 차량 에셋) | C8: =VLOOKUP($A8,WBS_계획!$A:$O,6,FALSE()) -> 공동 | D8: =VLOOKUP($A8,WBS_계획!$A:$O,12,FALSE()) -> 미착수 | E8: =IF(ISNUMBER(VLOOKUP($A8,WBS_계획!$A:$O,7,FALSE())),IF(AND(E$5>=VLOOKUP($A8,WBS_계획!$A:$O,7,FALSE()),E$5<=VLOOKUP($A8,WBS_계획!$A:$O,8,FALSE())),IF(LEFT($A8,1)="M","◆","■"),""),"") -> ■ | F8: =IF(ISNUMBER(VLOOKUP($A8,WBS_계획!$A:$O,7,FALSE())),IF(AND(F$5>=VLOOKUP($A8,WBS_계획!$A:$O,7,FALSE()),F$5<=VLOOKUP($A8,WBS_계획!$A:$O,8,FALSE())),IF(LEFT($A8,1)="M","◆","■"),""),"") | G8: =IF(ISNUMBER(VLOOKUP($A8,WBS_계획!$A:$O,7,FALSE())),IF(AND(G$5>=VLOOKUP($A8,WBS_계획!$A:$O,7,FALSE()),G$5<=VLOOKUP($A8,WBS_계획!$A:$O,8,FALSE())),IF(LEFT($A8,1)="M","◆","■"),""),"") | H8: =IF(ISNUMBER(VLOOKUP($A8,WBS_계획!$A:$O,7,FALSE())),IF(AND(H$5>=VLOOKUP($A8,WBS_계획!$A:$O,7,FALSE()),H$5<=VLOOKUP($A8,WBS_계획!$A:$O,8,FALSE())),IF(LEFT($A8,1)="M","◆","■"),""),"") | I8: =IF(ISNUMBER(VLOOKUP($A8,WBS_계획!$A:$O,7,FALSE())),IF(AND(I$5>=VLOOKUP($A8,WBS_계획!$A:$O,7,FALSE()),I$5<=VLOOKUP($A8,WBS_계획!$A:$O,8,FALSE())),IF(LEFT($A8,1)="M","◆","■"),""),"") | J8: =IF(ISNUMBER(VLOOKUP($A8,WBS_계획!$A:$O,7,FALSE())),IF(AND(J$5>=VLOOKUP($A8,WBS_계획!$A:$O,7,FALSE()),J$5<=VLOOKUP($A8,WBS_계획!$A:$O,8,FALSE())),IF(LEFT($A8,1)="M","◆","■"),""),"") | K8: =IF(ISNUMBER(VLOOKUP($A8,WBS_계획!$A:$O,7,FALSE())),IF(AND(K$5>=VLOOKUP($A8,WBS_계획!$A:$O,7,FALSE()),K$5<=VLOOKUP($A8,WBS_계획!$A:$O,8,FALSE())),IF(LEFT($A8,1)="M","◆","■"),""),"") | L8: =IF(ISNUMBER(VLOOKUP($A8,WBS_계획!$A:$O,7,FALSE())),IF(AND(L$5>=VLOOKUP($A8,WBS_계획!$A:$O,7,FALSE()),L$5<=VLOOKUP($A8,WBS_계획!$A:$O,8,FALSE())),IF(LEFT($A8,1)="M","◆","■"),""),"") | M8: =IF(ISNUMBER(VLOOKUP($A8,WBS_계획!$A:$O,7,FALSE())),IF(AND(M$5>=VLOOKUP($A8,WBS_계획!$A:$O,7,FALSE()),M$5<=VLOOKUP($A8,WBS_계획!$A:$O,8,FALSE())),IF(LEFT($A8,1)="M","◆","■"),""),"")
A9: A.4 | B9: =VLOOKUP($A9,WBS_계획!$A:$O,4,FALSE()) -> GitHub 저장소·main/dev 브랜치, .gitignore, Git LFS, Force Text | C9: =VLOOKUP($A9,WBS_계획!$A:$O,6,FALSE()) -> 김예은 | D9: =VLOOKUP($A9,WBS_계획!$A:$O,12,FALSE()) -> 미착수 | E9: =IF(ISNUMBER(VLOOKUP($A9,WBS_계획!$A:$O,7,FALSE())),IF(AND(E$5>=VLOOKUP($A9,WBS_계획!$A:$O,7,FALSE()),E$5<=VLOOKUP($A9,WBS_계획!$A:$O,8,FALSE())),IF(LEFT($A9,1)="M","◆","■"),""),"") -> ■ | F9: =IF(ISNUMBER(VLOOKUP($A9,WBS_계획!$A:$O,7,FALSE())),IF(AND(F$5>=VLOOKUP($A9,WBS_계획!$A:$O,7,FALSE()),F$5<=VLOOKUP($A9,WBS_계획!$A:$O,8,FALSE())),IF(LEFT($A9,1)="M","◆","■"),""),"") | G9: =IF(ISNUMBER(VLOOKUP($A9,WBS_계획!$A:$O,7,FALSE())),IF(AND(G$5>=VLOOKUP($A9,WBS_계획!$A:$O,7,FALSE()),G$5<=VLOOKUP($A9,WBS_계획!$A:$O,8,FALSE())),IF(LEFT($A9,1)="M","◆","■"),""),"") | H9: =IF(ISNUMBER(VLOOKUP($A9,WBS_계획!$A:$O,7,FALSE())),IF(AND(H$5>=VLOOKUP($A9,WBS_계획!$A:$O,7,FALSE()),H$5<=VLOOKUP($A9,WBS_계획!$A:$O,8,FALSE())),IF(LEFT($A9,1)="M","◆","■"),""),"") | I9: =IF(ISNUMBER(VLOOKUP($A9,WBS_계획!$A:$O,7,FALSE())),IF(AND(I$5>=VLOOKUP($A9,WBS_계획!$A:$O,7,FALSE()),I$5<=VLOOKUP($A9,WBS_계획!$A:$O,8,FALSE())),IF(LEFT($A9,1)="M","◆","■"),""),"") | J9: =IF(ISNUMBER(VLOOKUP($A9,WBS_계획!$A:$O,7,FALSE())),IF(AND(J$5>=VLOOKUP($A9,WBS_계획!$A:$O,7,FALSE()),J$5<=VLOOKUP($A9,WBS_계획!$A:$O,8,FALSE())),IF(LEFT($A9,1)="M","◆","■"),""),"") | K9: =IF(ISNUMBER(VLOOKUP($A9,WBS_계획!$A:$O,7,FALSE())),IF(AND(K$5>=VLOOKUP($A9,WBS_계획!$A:$O,7,FALSE()),K$5<=VLOOKUP($A9,WBS_계획!$A:$O,8,FALSE())),IF(LEFT($A9,1)="M","◆","■"),""),"") | L9: =IF(ISNUMBER(VLOOKUP($A9,WBS_계획!$A:$O,7,FALSE())),IF(AND(L$5>=VLOOKUP($A9,WBS_계획!$A:$O,7,FALSE()),L$5<=VLOOKUP($A9,WBS_계획!$A:$O,8,FALSE())),IF(LEFT($A9,1)="M","◆","■"),""),"") | M9: =IF(ISNUMBER(VLOOKUP($A9,WBS_계획!$A:$O,7,FALSE())),IF(AND(M$5>=VLOOKUP($A9,WBS_계획!$A:$O,7,FALSE()),M$5<=VLOOKUP($A9,WBS_계획!$A:$O,8,FALSE())),IF(LEFT($A9,1)="M","◆","■"),""),"")
A10: A.5 | B10: =VLOOKUP($A10,WBS_계획!$A:$O,4,FALSE()) -> Unity 버전 통일, 두 PC에서 프로젝트 열기 확인 | C10: =VLOOKUP($A10,WBS_계획!$A:$O,6,FALSE()) -> 공동 | D10: =VLOOKUP($A10,WBS_계획!$A:$O,12,FALSE()) -> 미착수 | E10: =IF(ISNUMBER(VLOOKUP($A10,WBS_계획!$A:$O,7,FALSE())),IF(AND(E$5>=VLOOKUP($A10,WBS_계획!$A:$O,7,FALSE()),E$5<=VLOOKUP($A10,WBS_계획!$A:$O,8,FALSE())),IF(LEFT($A10,1)="M","◆","■"),""),"") -> ■ | F10: =IF(ISNUMBER(VLOOKUP($A10,WBS_계획!$A:$O,7,FALSE())),IF(AND(F$5>=VLOOKUP($A10,WBS_계획!$A:$O,7,FALSE()),F$5<=VLOOKUP($A10,WBS_계획!$A:$O,8,FALSE())),IF(LEFT($A10,1)="M","◆","■"),""),"") | G10: =IF(ISNUMBER(VLOOKUP($A10,WBS_계획!$A:$O,7,FALSE())),IF(AND(G$5>=VLOOKUP($A10,WBS_계획!$A:$O,7,FALSE()),G$5<=VLOOKUP($A10,WBS_계획!$A:$O,8,FALSE())),IF(LEFT($A10,1)="M","◆","■"),""),"") | H10: =IF(ISNUMBER(VLOOKUP($A10,WBS_계획!$A:$O,7,FALSE())),IF(AND(H$5>=VLOOKUP($A10,WBS_계획!$A:$O,7,FALSE()),H$5<=VLOOKUP($A10,WBS_계획!$A:$O,8,FALSE())),IF(LEFT($A10,1)="M","◆","■"),""),"") | I10: =IF(ISNUMBER(VLOOKUP($A10,WBS_계획!$A:$O,7,FALSE())),IF(AND(I$5>=VLOOKUP($A10,WBS_계획!$A:$O,7,FALSE()),I$5<=VLOOKUP($A10,WBS_계획!$A:$O,8,FALSE())),IF(LEFT($A10,1)="M","◆","■"),""),"") | J10: =IF(ISNUMBER(VLOOKUP($A10,WBS_계획!$A:$O,7,FALSE())),IF(AND(J$5>=VLOOKUP($A10,WBS_계획!$A:$O,7,FALSE()),J$5<=VLOOKUP($A10,WBS_계획!$A:$O,8,FALSE())),IF(LEFT($A10,1)="M","◆","■"),""),"") | K10: =IF(ISNUMBER(VLOOKUP($A10,WBS_계획!$A:$O,7,FALSE())),IF(AND(K$5>=VLOOKUP($A10,WBS_계획!$A:$O,7,FALSE()),K$5<=VLOOKUP($A10,WBS_계획!$A:$O,8,FALSE())),IF(LEFT($A10,1)="M","◆","■"),""),"") | L10: =IF(ISNUMBER(VLOOKUP($A10,WBS_계획!$A:$O,7,FALSE())),IF(AND(L$5>=VLOOKUP($A10,WBS_계획!$A:$O,7,FALSE()),L$5<=VLOOKUP($A10,WBS_계획!$A:$O,8,FALSE())),IF(LEFT($A10,1)="M","◆","■"),""),"") | M10: =IF(ISNUMBER(VLOOKUP($A10,WBS_계획!$A:$O,7,FALSE())),IF(AND(M$5>=VLOOKUP($A10,WBS_계획!$A:$O,7,FALSE()),M$5<=VLOOKUP($A10,WBS_계획!$A:$O,8,FALSE())),IF(LEFT($A10,1)="M","◆","■"),""),"")
A11: A.6 | B11: =VLOOKUP($A11,WBS_계획!$A:$O,4,FALSE()) -> WBS·간트 관리, 매일 19:00 진척 갱신 | C11: =VLOOKUP($A11,WBS_계획!$A:$O,6,FALSE()) -> 공동 | D11: =VLOOKUP($A11,WBS_계획!$A:$O,12,FALSE()) -> 진행중 | E11: =IF(ISNUMBER(VLOOKUP($A11,WBS_계획!$A:$O,7,FALSE())),IF(AND(E$5>=VLOOKUP($A11,WBS_계획!$A:$O,7,FALSE()),E$5<=VLOOKUP($A11,WBS_계획!$A:$O,8,FALSE())),IF(LEFT($A11,1)="M","◆","■"),""),"") -> ■ | F11: =IF(ISNUMBER(VLOOKUP($A11,WBS_계획!$A:$O,7,FALSE())),IF(AND(F$5>=VLOOKUP($A11,WBS_계획!$A:$O,7,FALSE()),F$5<=VLOOKUP($A11,WBS_계획!$A:$O,8,FALSE())),IF(LEFT($A11,1)="M","◆","■"),""),"") -> ■ | G11: =IF(ISNUMBER(VLOOKUP($A11,WBS_계획!$A:$O,7,FALSE())),IF(AND(G$5>=VLOOKUP($A11,WBS_계획!$A:$O,7,FALSE()),G$5<=VLOOKUP($A11,WBS_계획!$A:$O,8,FALSE())),IF(LEFT($A11,1)="M","◆","■"),""),"") -> ■ | H11: =IF(ISNUMBER(VLOOKUP($A11,WBS_계획!$A:$O,7,FALSE())),IF(AND(H$5>=VLOOKUP($A11,WBS_계획!$A:$O,7,FALSE()),H$5<=VLOOKUP($A11,WBS_계획!$A:$O,8,FALSE())),IF(LEFT($A11,1)="M","◆","■"),""),"") -> ■ | I11: =IF(ISNUMBER(VLOOKUP($A11,WBS_계획!$A:$O,7,FALSE())),IF(AND(I$5>=VLOOKUP($A11,WBS_계획!$A:$O,7,FALSE()),I$5<=VLOOKUP($A11,WBS_계획!$A:$O,8,FALSE())),IF(LEFT($A11,1)="M","◆","■"),""),"") -> ■ | J11: =IF(ISNUMBER(VLOOKUP($A11,WBS_계획!$A:$O,7,FALSE())),IF(AND(J$5>=VLOOKUP($A11,WBS_계획!$A:$O,7,FALSE()),J$5<=VLOOKUP($A11,WBS_계획!$A:$O,8,FALSE())),IF(LEFT($A11,1)="M","◆","■"),""),"") -> ■ | K11: =IF(ISNUMBER(VLOOKUP($A11,WBS_계획!$A:$O,7,FALSE())),IF(AND(K$5>=VLOOKUP($A11,WBS_계획!$A:$O,7,FALSE()),K$5<=VLOOKUP($A11,WBS_계획!$A:$O,8,FALSE())),IF(LEFT($A11,1)="M","◆","■"),""),"") -> ■ | L11: =IF(ISNUMBER(VLOOKUP($A11,WBS_계획!$A:$O,7,FALSE())),IF(AND(L$5>=VLOOKUP($A11,WBS_계획!$A:$O,7,FALSE()),L$5<=VLOOKUP($A11,WBS_계획!$A:$O,8,FALSE())),IF(LEFT($A11,1)="M","◆","■"),""),"") -> ■ | M11: =IF(ISNUMBER(VLOOKUP($A11,WBS_계획!$A:$O,7,FALSE())),IF(AND(M$5>=VLOOKUP($A11,WBS_계획!$A:$O,7,FALSE()),M$5<=VLOOKUP($A11,WBS_계획!$A:$O,8,FALSE())),IF(LEFT($A11,1)="M","◆","■"),""),"") -> ■
A12: B.1 | B12: =VLOOKUP($A12,WBS_계획!$A:$O,4,FALSE()) -> MainScene·ModeManager·AreaBase (Additive 로드·전환·초기화) | C12: =VLOOKUP($A12,WBS_계획!$A:$O,6,FALSE()) -> 김예은 | D12: =VLOOKUP($A12,WBS_계획!$A:$O,12,FALSE()) -> 미착수 | E12: =IF(ISNUMBER(VLOOKUP($A12,WBS_계획!$A:$O,7,FALSE())),IF(AND(E$5>=VLOOKUP($A12,WBS_계획!$A:$O,7,FALSE()),E$5<=VLOOKUP($A12,WBS_계획!$A:$O,8,FALSE())),IF(LEFT($A12,1)="M","◆","■"),""),"") | F12: =IF(ISNUMBER(VLOOKUP($A12,WBS_계획!$A:$O,7,FALSE())),IF(AND(F$5>=VLOOKUP($A12,WBS_계획!$A:$O,7,FALSE()),F$5<=VLOOKUP($A12,WBS_계획!$A:$O,8,FALSE())),IF(LEFT($A12,1)="M","◆","■"),""),"") -> ■ | G12: =IF(ISNUMBER(VLOOKUP($A12,WBS_계획!$A:$O,7,FALSE())),IF(AND(G$5>=VLOOKUP($A12,WBS_계획!$A:$O,7,FALSE()),G$5<=VLOOKUP($A12,WBS_계획!$A:$O,8,FALSE())),IF(LEFT($A12,1)="M","◆","■"),""),"") | H12: =IF(ISNUMBER(VLOOKUP($A12,WBS_계획!$A:$O,7,FALSE())),IF(AND(H$5>=VLOOKUP($A12,WBS_계획!$A:$O,7,FALSE()),H$5<=VLOOKUP($A12,WBS_계획!$A:$O,8,FALSE())),IF(LEFT($A12,1)="M","◆","■"),""),"") | I12: =IF(ISNUMBER(VLOOKUP($A12,WBS_계획!$A:$O,7,FALSE())),IF(AND(I$5>=VLOOKUP($A12,WBS_계획!$A:$O,7,FALSE()),I$5<=VLOOKUP($A12,WBS_계획!$A:$O,8,FALSE())),IF(LEFT($A12,1)="M","◆","■"),""),"") | J12: =IF(ISNUMBER(VLOOKUP($A12,WBS_계획!$A:$O,7,FALSE())),IF(AND(J$5>=VLOOKUP($A12,WBS_계획!$A:$O,7,FALSE()),J$5<=VLOOKUP($A12,WBS_계획!$A:$O,8,FALSE())),IF(LEFT($A12,1)="M","◆","■"),""),"") | K12: =IF(ISNUMBER(VLOOKUP($A12,WBS_계획!$A:$O,7,FALSE())),IF(AND(K$5>=VLOOKUP($A12,WBS_계획!$A:$O,7,FALSE()),K$5<=VLOOKUP($A12,WBS_계획!$A:$O,8,FALSE())),IF(LEFT($A12,1)="M","◆","■"),""),"") | L12: =IF(ISNUMBER(VLOOKUP($A12,WBS_계획!$A:$O,7,FALSE())),IF(AND(L$5>=VLOOKUP($A12,WBS_계획!$A:$O,7,FALSE()),L$5<=VLOOKUP($A12,WBS_계획!$A:$O,8,FALSE())),IF(LEFT($A12,1)="M","◆","■"),""),"") | M12: =IF(ISNUMBER(VLOOKUP($A12,WBS_계획!$A:$O,7,FALSE())),IF(AND(M$5>=VLOOKUP($A12,WBS_계획!$A:$O,7,FALSE()),M$5<=VLOOKUP($A12,WBS_계획!$A:$O,8,FALSE())),IF(LEFT($A12,1)="M","◆","■"),""),"")
A13: B.2 | B13: =VLOOKUP($A13,WBS_계획!$A:$O,4,FALSE()) -> 공통 차량 프리팹, CarController (WheelCollider, 스크립트 입력) | C13: =VLOOKUP($A13,WBS_계획!$A:$O,6,FALSE()) -> 김예은 | D13: =VLOOKUP($A13,WBS_계획!$A:$O,12,FALSE()) -> 미착수 | E13: =IF(ISNUMBER(VLOOKUP($A13,WBS_계획!$A:$O,7,FALSE())),IF(AND(E$5>=VLOOKUP($A13,WBS_계획!$A:$O,7,FALSE()),E$5<=VLOOKUP($A13,WBS_계획!$A:$O,8,FALSE())),IF(LEFT($A13,1)="M","◆","■"),""),"") | F13: =IF(ISNUMBER(VLOOKUP($A13,WBS_계획!$A:$O,7,FALSE())),IF(AND(F$5>=VLOOKUP($A13,WBS_계획!$A:$O,7,FALSE()),F$5<=VLOOKUP($A13,WBS_계획!$A:$O,8,FALSE())),IF(LEFT($A13,1)="M","◆","■"),""),"") -> ■ | G13: =IF(ISNUMBER(VLOOKUP($A13,WBS_계획!$A:$O,7,FALSE())),IF(AND(G$5>=VLOOKUP($A13,WBS_계획!$A:$O,7,FALSE()),G$5<=VLOOKUP($A13,WBS_계획!$A:$O,8,FALSE())),IF(LEFT($A13,1)="M","◆","■"),""),"") | H13: =IF(ISNUMBER(VLOOKUP($A13,WBS_계획!$A:$O,7,FALSE())),IF(AND(H$5>=VLOOKUP($A13,WBS_계획!$A:$O,7,FALSE()),H$5<=VLOOKUP($A13,WBS_계획!$A:$O,8,FALSE())),IF(LEFT($A13,1)="M","◆","■"),""),"") | I13: =IF(ISNUMBER(VLOOKUP($A13,WBS_계획!$A:$O,7,FALSE())),IF(AND(I$5>=VLOOKUP($A13,WBS_계획!$A:$O,7,FALSE()),I$5<=VLOOKUP($A13,WBS_계획!$A:$O,8,FALSE())),IF(LEFT($A13,1)="M","◆","■"),""),"") | J13: =IF(ISNUMBER(VLOOKUP($A13,WBS_계획!$A:$O,7,FALSE())),IF(AND(J$5>=VLOOKUP($A13,WBS_계획!$A:$O,7,FALSE()),J$5<=VLOOKUP($A13,WBS_계획!$A:$O,8,FALSE())),IF(LEFT($A13,1)="M","◆","■"),""),"") | K13: =IF(ISNUMBER(VLOOKUP($A13,WBS_계획!$A:$O,7,FALSE())),IF(AND(K$5>=VLOOKUP($A13,WBS_계획!$A:$O,7,FALSE()),K$5<=VLOOKUP($A13,WBS_계획!$A:$O,8,FALSE())),IF(LEFT($A13,1)="M","◆","■"),""),"") | L13: =IF(ISNUMBER(VLOOKUP($A13,WBS_계획!$A:$O,7,FALSE())),IF(AND(L$5>=VLOOKUP($A13,WBS_계획!$A:$O,7,FALSE()),L$5<=VLOOKUP($A13,WBS_계획!$A:$O,8,FALSE())),IF(LEFT($A13,1)="M","◆","■"),""),"") | M13: =IF(ISNUMBER(VLOOKUP($A13,WBS_계획!$A:$O,7,FALSE())),IF(AND(M$5>=VLOOKUP($A13,WBS_계획!$A:$O,7,FALSE()),M$5<=VLOOKUP($A13,WBS_계획!$A:$O,8,FALSE())),IF(LEFT($A13,1)="M","◆","■"),""),"")
A14: B.3 | B14: =VLOOKUP($A14,WBS_계획!$A:$O,4,FALSE()) -> ConfiguratorArea 쇼룸, UI-01 외관 선택, UI-02 기능 선택 | C14: =VLOOKUP($A14,WBS_계획!$A:$O,6,FALSE()) -> 강유나 | D14: =VLOOKUP($A14,WBS_계획!$A:$O,12,FALSE()) -> 미착수 | E14: =IF(ISNUMBER(VLOOKUP($A14,WBS_계획!$A:$O,7,FALSE())),IF(AND(E$5>=VLOOKUP($A14,WBS_계획!$A:$O,7,FALSE()),E$5<=VLOOKUP($A14,WBS_계획!$A:$O,8,FALSE())),IF(LEFT($A14,1)="M","◆","■"),""),"") | F14: =IF(ISNUMBER(VLOOKUP($A14,WBS_계획!$A:$O,7,FALSE())),IF(AND(F$5>=VLOOKUP($A14,WBS_계획!$A:$O,7,FALSE()),F$5<=VLOOKUP($A14,WBS_계획!$A:$O,8,FALSE())),IF(LEFT($A14,1)="M","◆","■"),""),"") -> ■ | G14: =IF(ISNUMBER(VLOOKUP($A14,WBS_계획!$A:$O,7,FALSE())),IF(AND(G$5>=VLOOKUP($A14,WBS_계획!$A:$O,7,FALSE()),G$5<=VLOOKUP($A14,WBS_계획!$A:$O,8,FALSE())),IF(LEFT($A14,1)="M","◆","■"),""),"") | H14: =IF(ISNUMBER(VLOOKUP($A14,WBS_계획!$A:$O,7,FALSE())),IF(AND(H$5>=VLOOKUP($A14,WBS_계획!$A:$O,7,FALSE()),H$5<=VLOOKUP($A14,WBS_계획!$A:$O,8,FALSE())),IF(LEFT($A14,1)="M","◆","■"),""),"") | I14: =IF(ISNUMBER(VLOOKUP($A14,WBS_계획!$A:$O,7,FALSE())),IF(AND(I$5>=VLOOKUP($A14,WBS_계획!$A:$O,7,FALSE()),I$5<=VLOOKUP($A14,WBS_계획!$A:$O,8,FALSE())),IF(LEFT($A14,1)="M","◆","■"),""),"") | J14: =IF(ISNUMBER(VLOOKUP($A14,WBS_계획!$A:$O,7,FALSE())),IF(AND(J$5>=VLOOKUP($A14,WBS_계획!$A:$O,7,FALSE()),J$5<=VLOOKUP($A14,WBS_계획!$A:$O,8,FALSE())),IF(LEFT($A14,1)="M","◆","■"),""),"") | K14: =IF(ISNUMBER(VLOOKUP($A14,WBS_계획!$A:$O,7,FALSE())),IF(AND(K$5>=VLOOKUP($A14,WBS_계획!$A:$O,7,FALSE()),K$5<=VLOOKUP($A14,WBS_계획!$A:$O,8,FALSE())),IF(LEFT($A14,1)="M","◆","■"),""),"") | L14: =IF(ISNUMBER(VLOOKUP($A14,WBS_계획!$A:$O,7,FALSE())),IF(AND(L$5>=VLOOKUP($A14,WBS_계획!$A:$O,7,FALSE()),L$5<=VLOOKUP($A14,WBS_계획!$A:$O,8,FALSE())),IF(LEFT($A14,1)="M","◆","■"),""),"") | M14: =IF(ISNUMBER(VLOOKUP($A14,WBS_계획!$A:$O,7,FALSE())),IF(AND(M$5>=VLOOKUP($A14,WBS_계획!$A:$O,7,FALSE()),M$5<=VLOOKUP($A14,WBS_계획!$A:$O,8,FALSE())),IF(LEFT($A14,1)="M","◆","■"),""),"")
A15: B.4 | B15: =VLOOKUP($A15,WBS_계획!$A:$O,4,FALSE()) -> CarConfig, CarAppearance (색상·트림·휠) | C15: =VLOOKUP($A15,WBS_계획!$A:$O,6,FALSE()) -> 강유나 | D15: =VLOOKUP($A15,WBS_계획!$A:$O,12,FALSE()) -> 미착수 | E15: =IF(ISNUMBER(VLOOKUP($A15,WBS_계획!$A:$O,7,FALSE())),IF(AND(E$5>=VLOOKUP($A15,WBS_계획!$A:$O,7,FALSE()),E$5<=VLOOKUP($A15,WBS_계획!$A:$O,8,FALSE())),IF(LEFT($A15,1)="M","◆","■"),""),"") | F15: =IF(ISNUMBER(VLOOKUP($A15,WBS_계획!$A:$O,7,FALSE())),IF(AND(F$5>=VLOOKUP($A15,WBS_계획!$A:$O,7,FALSE()),F$5<=VLOOKUP($A15,WBS_계획!$A:$O,8,FALSE())),IF(LEFT($A15,1)="M","◆","■"),""),"") -> ■ | G15: =IF(ISNUMBER(VLOOKUP($A15,WBS_계획!$A:$O,7,FALSE())),IF(AND(G$5>=VLOOKUP($A15,WBS_계획!$A:$O,7,FALSE()),G$5<=VLOOKUP($A15,WBS_계획!$A:$O,8,FALSE())),IF(LEFT($A15,1)="M","◆","■"),""),"") | H15: =IF(ISNUMBER(VLOOKUP($A15,WBS_계획!$A:$O,7,FALSE())),IF(AND(H$5>=VLOOKUP($A15,WBS_계획!$A:$O,7,FALSE()),H$5<=VLOOKUP($A15,WBS_계획!$A:$O,8,FALSE())),IF(LEFT($A15,1)="M","◆","■"),""),"") | I15: =IF(ISNUMBER(VLOOKUP($A15,WBS_계획!$A:$O,7,FALSE())),IF(AND(I$5>=VLOOKUP($A15,WBS_계획!$A:$O,7,FALSE()),I$5<=VLOOKUP($A15,WBS_계획!$A:$O,8,FALSE())),IF(LEFT($A15,1)="M","◆","■"),""),"") | J15: =IF(ISNUMBER(VLOOKUP($A15,WBS_계획!$A:$O,7,FALSE())),IF(AND(J$5>=VLOOKUP($A15,WBS_계획!$A:$O,7,FALSE()),J$5<=VLOOKUP($A15,WBS_계획!$A:$O,8,FALSE())),IF(LEFT($A15,1)="M","◆","■"),""),"") | K15: =IF(ISNUMBER(VLOOKUP($A15,WBS_계획!$A:$O,7,FALSE())),IF(AND(K$5>=VLOOKUP($A15,WBS_계획!$A:$O,7,FALSE()),K$5<=VLOOKUP($A15,WBS_계획!$A:$O,8,FALSE())),IF(LEFT($A15,1)="M","◆","■"),""),"") | L15: =IF(ISNUMBER(VLOOKUP($A15,WBS_계획!$A:$O,7,FALSE())),IF(AND(L$5>=VLOOKUP($A15,WBS_계획!$A:$O,7,FALSE()),L$5<=VLOOKUP($A15,WBS_계획!$A:$O,8,FALSE())),IF(LEFT($A15,1)="M","◆","■"),""),"") | M15: =IF(ISNUMBER(VLOOKUP($A15,WBS_계획!$A:$O,7,FALSE())),IF(AND(M$5>=VLOOKUP($A15,WBS_계획!$A:$O,7,FALSE()),M$5<=VLOOKUP($A15,WBS_계획!$A:$O,8,FALSE())),IF(LEFT($A15,1)="M","◆","■"),""),"")
A16: B.5 | B16: =VLOOKUP($A16,WBS_계획!$A:$O,4,FALSE()) -> SplitScreenManager, CameraSwitcher | C16: =VLOOKUP($A16,WBS_계획!$A:$O,6,FALSE()) -> 공동 | D16: =VLOOKUP($A16,WBS_계획!$A:$O,12,FALSE()) -> 미착수 | E16: =IF(ISNUMBER(VLOOKUP($A16,WBS_계획!$A:$O,7,FALSE())),IF(AND(E$5>=VLOOKUP($A16,WBS_계획!$A:$O,7,FALSE()),E$5<=VLOOKUP($A16,WBS_계획!$A:$O,8,FALSE())),IF(LEFT($A16,1)="M","◆","■"),""),"") | F16: =IF(ISNUMBER(VLOOKUP($A16,WBS_계획!$A:$O,7,FALSE())),IF(AND(F$5>=VLOOKUP($A16,WBS_계획!$A:$O,7,FALSE()),F$5<=VLOOKUP($A16,WBS_계획!$A:$O,8,FALSE())),IF(LEFT($A16,1)="M","◆","■"),""),"") | G16: =IF(ISNUMBER(VLOOKUP($A16,WBS_계획!$A:$O,7,FALSE())),IF(AND(G$5>=VLOOKUP($A16,WBS_계획!$A:$O,7,FALSE()),G$5<=VLOOKUP($A16,WBS_계획!$A:$O,8,FALSE())),IF(LEFT($A16,1)="M","◆","■"),""),"") -> ■ | H16: =IF(ISNUMBER(VLOOKUP($A16,WBS_계획!$A:$O,7,FALSE())),IF(AND(H$5>=VLOOKUP($A16,WBS_계획!$A:$O,7,FALSE()),H$5<=VLOOKUP($A16,WBS_계획!$A:$O,8,FALSE())),IF(LEFT($A16,1)="M","◆","■"),""),"") | I16: =IF(ISNUMBER(VLOOKUP($A16,WBS_계획!$A:$O,7,FALSE())),IF(AND(I$5>=VLOOKUP($A16,WBS_계획!$A:$O,7,FALSE()),I$5<=VLOOKUP($A16,WBS_계획!$A:$O,8,FALSE())),IF(LEFT($A16,1)="M","◆","■"),""),"") | J16: =IF(ISNUMBER(VLOOKUP($A16,WBS_계획!$A:$O,7,FALSE())),IF(AND(J$5>=VLOOKUP($A16,WBS_계획!$A:$O,7,FALSE()),J$5<=VLOOKUP($A16,WBS_계획!$A:$O,8,FALSE())),IF(LEFT($A16,1)="M","◆","■"),""),"") | K16: =IF(ISNUMBER(VLOOKUP($A16,WBS_계획!$A:$O,7,FALSE())),IF(AND(K$5>=VLOOKUP($A16,WBS_계획!$A:$O,7,FALSE()),K$5<=VLOOKUP($A16,WBS_계획!$A:$O,8,FALSE())),IF(LEFT($A16,1)="M","◆","■"),""),"") | L16: =IF(ISNUMBER(VLOOKUP($A16,WBS_계획!$A:$O,7,FALSE())),IF(AND(L$5>=VLOOKUP($A16,WBS_계획!$A:$O,7,FALSE()),L$5<=VLOOKUP($A16,WBS_계획!$A:$O,8,FALSE())),IF(LEFT($A16,1)="M","◆","■"),""),"") | M16: =IF(ISNUMBER(VLOOKUP($A16,WBS_계획!$A:$O,7,FALSE())),IF(AND(M$5>=VLOOKUP($A16,WBS_계획!$A:$O,7,FALSE()),M$5<=VLOOKUP($A16,WBS_계획!$A:$O,8,FALSE())),IF(LEFT($A16,1)="M","◆","■"),""),"")
A17: B.6 | B17: =VLOOKUP($A17,WBS_계획!$A:$O,4,FALSE()) -> 공통 기반 dev 병합, 두 PC에서 모드 전환 확인 | C17: =VLOOKUP($A17,WBS_계획!$A:$O,6,FALSE()) -> 공동 | D17: =VLOOKUP($A17,WBS_계획!$A:$O,12,FALSE()) -> 미착수 | E17: =IF(ISNUMBER(VLOOKUP($A17,WBS_계획!$A:$O,7,FALSE())),IF(AND(E$5>=VLOOKUP($A17,WBS_계획!$A:$O,7,FALSE()),E$5<=VLOOKUP($A17,WBS_계획!$A:$O,8,FALSE())),IF(LEFT($A17,1)="M","◆","■"),""),"") | F17: =IF(ISNUMBER(VLOOKUP($A17,WBS_계획!$A:$O,7,FALSE())),IF(AND(F$5>=VLOOKUP($A17,WBS_계획!$A:$O,7,FALSE()),F$5<=VLOOKUP($A17,WBS_계획!$A:$O,8,FALSE())),IF(LEFT($A17,1)="M","◆","■"),""),"") -> ■ | G17: =IF(ISNUMBER(VLOOKUP($A17,WBS_계획!$A:$O,7,FALSE())),IF(AND(G$5>=VLOOKUP($A17,WBS_계획!$A:$O,7,FALSE()),G$5<=VLOOKUP($A17,WBS_계획!$A:$O,8,FALSE())),IF(LEFT($A17,1)="M","◆","■"),""),"") | H17: =IF(ISNUMBER(VLOOKUP($A17,WBS_계획!$A:$O,7,FALSE())),IF(AND(H$5>=VLOOKUP($A17,WBS_계획!$A:$O,7,FALSE()),H$5<=VLOOKUP($A17,WBS_계획!$A:$O,8,FALSE())),IF(LEFT($A17,1)="M","◆","■"),""),"") | I17: =IF(ISNUMBER(VLOOKUP($A17,WBS_계획!$A:$O,7,FALSE())),IF(AND(I$5>=VLOOKUP($A17,WBS_계획!$A:$O,7,FALSE()),I$5<=VLOOKUP($A17,WBS_계획!$A:$O,8,FALSE())),IF(LEFT($A17,1)="M","◆","■"),""),"") | J17: =IF(ISNUMBER(VLOOKUP($A17,WBS_계획!$A:$O,7,FALSE())),IF(AND(J$5>=VLOOKUP($A17,WBS_계획!$A:$O,7,FALSE()),J$5<=VLOOKUP($A17,WBS_계획!$A:$O,8,FALSE())),IF(LEFT($A17,1)="M","◆","■"),""),"") | K17: =IF(ISNUMBER(VLOOKUP($A17,WBS_계획!$A:$O,7,FALSE())),IF(AND(K$5>=VLOOKUP($A17,WBS_계획!$A:$O,7,FALSE()),K$5<=VLOOKUP($A17,WBS_계획!$A:$O,8,FALSE())),IF(LEFT($A17,1)="M","◆","■"),""),"") | L17: =IF(ISNUMBER(VLOOKUP($A17,WBS_계획!$A:$O,7,FALSE())),IF(AND(L$5>=VLOOKUP($A17,WBS_계획!$A:$O,7,FALSE()),L$5<=VLOOKUP($A17,WBS_계획!$A:$O,8,FALSE())),IF(LEFT($A17,1)="M","◆","■"),""),"") | M17: =IF(ISNUMBER(VLOOKUP($A17,WBS_계획!$A:$O,7,FALSE())),IF(AND(M$5>=VLOOKUP($A17,WBS_계획!$A:$O,7,FALSE()),M$5<=VLOOKUP($A17,WBS_계획!$A:$O,8,FALSE())),IF(LEFT($A17,1)="M","◆","■"),""),"")
... A54: M7 | B54: =VLOOKUP($A54,WBS_계획!$A:$O,4,FALSE()) -> 발표·제출 | C54: =VLOOKUP($A54,WBS_계획!$A:$O,6,FALSE()) -> 공동 | D54: =VLOOKUP($A54,WBS_계획!$A:$O,12,FALSE()) -> 미착수 | E54: =IF(ISNUMBER(VLOOKUP($A54,WBS_계획!$A:$O,7,FALSE())),IF(AND(E$5>=VLOOKUP($A54,WBS_계획!$A:$O,7,FALSE()),E$5<=VLOOKUP($A54,WBS_계획!$A:$O,8,FALSE())),IF(LEFT($A54,1)="M","◆","■"),""),"") | F54: =IF(ISNUMBER(VLOOKUP($A54,WBS_계획!$A:$O,7,FALSE())),IF(AND(F$5>=VLOOKUP($A54,WBS_계획!$A:$O,7,FALSE()),F$5<=VLOOKUP($A54,WBS_계획!$A:$O,8,FALSE())),IF(LEFT($A54,1)="M","◆","■"),""),"") | G54: =IF(ISNUMBER(VLOOKUP($A54,WBS_계획!$A:$O,7,FALSE())),IF(AND(G$5>=VLOOKUP($A54,WBS_계획!$A:$O,7,FALSE()),G$5<=VLOOKUP($A54,WBS_계획!$A:$O,8,FALSE())),IF(LEFT($A54,1)="M","◆","■"),""),"") | H54: =IF(ISNUMBER(VLOOKUP($A54,WBS_계획!$A:$O,7,FALSE())),IF(AND(H$5>=VLOOKUP($A54,WBS_계획!$A:$O,7,FALSE()),H$5<=VLOOKUP($A54,WBS_계획!$A:$O,8,FALSE())),IF(LEFT($A54,1)="M","◆","■"),""),"") | I54: =IF(ISNUMBER(VLOOKUP($A54,WBS_계획!$A:$O,7,FALSE())),IF(AND(I$5>=VLOOKUP($A54,WBS_계획!$A:$O,7,FALSE()),I$5<=VLOOKUP($A54,WBS_계획!$A:$O,8,FALSE())),IF(LEFT($A54,1)="M","◆","■"),""),"") | J54: =IF(ISNUMBER(VLOOKUP($A54,WBS_계획!$A:$O,7,FALSE())),IF(AND(J$5>=VLOOKUP($A54,WBS_계획!$A:$O,7,FALSE()),J$5<=VLOOKUP($A54,WBS_계획!$A:$O,8,FALSE())),IF(LEFT($A54,1)="M","◆","■"),""),"") | K54: =IF(ISNUMBER(VLOOKUP($A54,WBS_계획!$A:$O,7,FALSE())),IF(AND(K$5>=VLOOKUP($A54,WBS_계획!$A:$O,7,FALSE()),K$5<=VLOOKUP($A54,WBS_계획!$A:$O,8,FALSE())),IF(LEFT($A54,1)="M","◆","■"),""),"") | L54: =IF(ISNUMBER(VLOOKUP($A54,WBS_계획!$A:$O,7,FALSE())),IF(AND(L$5>=VLOOKUP($A54,WBS_계획!$A:$O,7,FALSE()),L$5<=VLOOKUP($A54,WBS_계획!$A:$O,8,FALSE())),IF(LEFT($A54,1)="M","◆","■"),""),"") | M54: =IF(ISNUMBER(VLOOKUP($A54,WBS_계획!$A:$O,7,FALSE())),IF(AND(M$5>=VLOOKUP($A54,WBS_계획!$A:$O,7,FALSE()),M$5<=VLOOKUP($A54,WBS_계획!$A:$O,8,FALSE())),IF(LEFT($A54,1)="M","◆","■"),""),"") -> ◆
